<?xml version="1.0"?>
<robot xmlns:xi="http://www.w3.org/2001/XInclude"
	xmlns:gazebo="http://playerstage.sourceforge.net/gazebo/xmlschema/#gz"
	xmlns:model="http://playerstage.sourceforge.net/gazebo/xmlschema/#model"
	xmlns:sensor="http://playerstage.sourceforge.net/gazebo/xmlschema/#sensor"
	xmlns:body="http://playerstage.sourceforge.net/gazebo/xmlschema/#body"
	xmlns:geom="http://playerstage.sourceforge.net/gazebo/xmlschema/#geom"
	xmlns:joint="http://playerstage.sourceforge.net/gazebo/xmlschema/#joint"
	xmlns:controller="http://playerstage.sourceforge.net/gazebo/xmlschema/#controller"
	xmlns:interface="http://playerstage.sourceforge.net/gazebo/xmlschema/#interface"
	xmlns:rendering="http://playerstage.sourceforge.net/gazebo/xmlschema/#rendering"
	xmlns:renderable="http://playerstage.sourceforge.net/gazebo/xmlschema/#renderable"
	xmlns:physics="http://playerstage.sourceforge.net/gazebo/xmlschema/#physics"
	xmlns:xacro="http://ros.org/wiki/xacro" name="robot1">

  <xacro:include filename="$(find move_group)/urdf/apc_description/urdf/kiva_pod.xacro"/>
  <xacro:include filename="$(find move_group)/urdf/apc_description/urdf/jaco_arm.xacro"/>
  <xacro:include filename="$(find move_group)/urdf/table.xacro"/>


  <link name="world_frame"/>
  

  <!--kiva description-->
  <xacro:kiva_pod parent="world_frame" />
  

  <!--robot description-->
  <joint name="world_to_robot_x" type="prismatic">
    <parent link="world_frame"/>
    <child link="virtual_base_link"/>
    <origin xyz="0 0 0" rpy="0 0 0"/>
    <axis xyz="1 0 0"/>
    <limit lower="-12.0" upper="12.0" effort="100" velocity="8.0"/>
  </joint>
  
  <link name="virtual_base_link"/>
  
  <joint name="world_to_robot_y" type="prismatic">
  	<parent link="virtual_base_link"/>
  	<child link="virtual_base_link_2"/>
  	<origin xyz="0 0 0" rpy="0 0 0"/>
  	<axis xyz="0 1 0"/>
  	<limit lower="-10.0" upper="10.0" effort="100" velocity="8.0"/>
  </joint>
  
  <link name="virtual_base_link_2"/>
  
  <joint name="world_to_robot_roll" type="continuous">
  	<parent link="virtual_base_link_2"/>
  	<child link="base_link"/>
  	<origin xyz="-1.5 -3.432 0.035" rpy="0 0 0"/>
  	<axis xyz="0 0 1"/>
  </joint>
  
  <link name="base_link">
  	<visual>
  		<origin rpy="0 0 0" xyz="0 0 0.195"/>
  		<geometry>
  			<box size="0.61 0.76 0.3125"/>
  		</geometry>
  		<material name="yellow">
  			<color rgba="1 1 0 1"/>
  		</material>
  	</visual>
  	<collision>
  		<origin rpy="0 0 0" xyz="0 0 0.195"/>
  		<geometry>
  			<box size="0.61 0.76 0.3125"/>
  		</geometry>
  	</collision>
  </link>
  
  <joint name="base_to_wheel1" type="fixed">
	<parent link="base_link"/>
	<child link="wheel_1"/>
	<origin rpy="0 0 0" xyz="0 0 0"/>
  </joint>
  
  <link name="wheel_1">
  <visual>
	<geometry>
	<cylinder length="0.048" radius="0.09"/>
	</geometry>
 	<origin rpy="0 1.571 0" xyz="0.262 0 0.078"/>
	<material name="black">
	<color rgba="0 0 0 1"/>
	</material>
  </visual>
  <collision>
	<origin rpy="0 1.571 0" xyz="0.262 0 0.078"/>
	<geometry>
	<cylinder length="0.048" radius="0.09"/>
	</geometry>
  </collision>
  <inertial>
	<mass value="10"/>
	<inertia ixx="1.0" ixy="0.0" ixz="0.0" iyy="1.0" iyz="0.0" izz="1.0"/>
  </inertial>
  </link>


 <joint name="base_to_wheel2" type="fixed">
	<parent link="base_link"/>
	<child link="wheel_2"/>
	<origin rpy="0 0 0" xyz="0 0 0"/>
  </joint>
  
  <link name="wheel_2">
  <visual>
	<geometry>
	<cylinder length="0.048" radius="0.09"/>
	</geometry>
 	<origin rpy="0 1.571 0" xyz="-0.262 0 0.078"/>
	<material name="black">
	<color rgba="0 0 0 1"/>
	</material>
  </visual>
  <collision>
	<origin rpy="0 1.571 0" xyz="-0.262 0 0.078"/>
	<geometry>
	<cylinder length="0.048" radius="0.09"/>
	</geometry>
  </collision>
  <inertial>
	<mass value="10"/>
	<inertia ixx="1.0" ixy="0.0" ixz="0.0" iyy="1.0" iyz="0.0" izz="1.0"/>
  </inertial>
  </link>


  <joint name="support_to_base" type="continuous">
  	<origin rpy="0 0 0" xyz="0 0 0.3225"/>
  	<parent link="base_link"/>
  	<child link="support_link"/>
  	<axis xyz="0 0 1"/>
  </joint>

  <link name="support_link">
    <inertial>
      <origin
        xyz="0.029769 -0.0126599999999999 0.97862"
        rpy="0 0 0" />
      <mass
        value="8.1734" />
      <inertia
        ixx="3.14464667119818"
        ixy="0.0415389708201151"
        ixz="-0.00168971152269903"
        iyy="-0.0861920217938598"
        iyz="-3.01021801246017"
        izz="0.08619202179386" />
    </inertial>
    <visual>
      <origin
        xyz="0 0 -0.28"
        rpy="1.5707963267949 0 -1.5707963267949" />
      <geometry>
        <mesh filename="package://move_group/urdf/support/meshes/support.STL" />
      </geometry>
      <material
        name="">
        <color
          rgba="1 1 1 1" />
      </material>
    </visual>
    <collision>
      <origin
        xyz="0 0 -0.28"
        rpy="1.5707963267949 0 -1.5707963267949" />
      <geometry>
        <mesh filename="package://move_group/urdf/support/meshes/support.STL" />
      </geometry>
    </collision>
  </link>
  
  <xacro:jaco_arm parent="support_link" prefix="jaco" xyz="0 0 1.22" rpy="3.141592653 -0.785 1.5707963267949"/>

  



<!--wall description-->

<joint name="world_to_wall_1" type="fixed">
    <parent link="world_frame"/>
    <child link="wall_1"/>
    <origin rpy="0 0 0" xyz="-0.612 -4.952 0"/>
  </joint>

 <link name="wall_1">
   <visual>
    <geometry>
     <box size="9.8 0.2 3.0"/>
    </geometry>
    <origin rpy="0 0 0" xyz="0 0 1.5"/>
    <material name="white">
     <color rgba="1 1 1 0.5"/>
    </material>
   </visual>
   <collision>
    <origin rpy="0 0 0" xyz="0 0 1.5"/>
    <geometry>
     <box size="9.8 0.2 3.0"/>
    </geometry>
   </collision>
   <inertial>
    <mass value="1000"/>
    <inertia ixx="1.0" ixy="0.0" ixz="0.0" iyy="1.0" iyz="0.0" izz="1.0"/>
   </inertial>
  </link>

<joint name="world_to_wall_2" type="fixed">
    <parent link="world_frame"/>
    <child link="wall_2"/>
    <origin rpy="0 0 0" xyz="-5.512 -1.037 0"/>
  </joint>

 <link name="wall_2">
   <visual>
    <geometry>
     <box size="0.2 7.63 3.0"/>
    </geometry>
    <origin rpy="0 0 0" xyz="0 0 1.5"/>
    <material name="white">
     <color rgba="1 1 1 0.5"/>
    </material>
   </visual>
   <collision>
    <origin rpy="0 0 0" xyz="0 0 1.5"/>
    <geometry>
     <box size="0.2 7.63 3.0"/>
    </geometry>
   </collision>
   <inertial>
    <mass value="1000"/>
    <inertia ixx="1.0" ixy="0.0" ixz="0.0" iyy="1.0" iyz="0.0" izz="1.0"/>
   </inertial>
  </link>

<joint name="world_to_wall_3" type="fixed">
    <parent link="world_frame"/>
    <child link="wall_3"/>
    <origin rpy="0 0 0" xyz="-0.612 2.878 0"/>
  </joint>

 <link name="wall_3">
   <visual>
    <geometry>
     <box size="9.8 0.2 3.0"/>
    </geometry>
    <origin rpy="0 0 0" xyz="0 0 1.5"/>
    <material name="white">
     <color rgba="1 1 1 0.5"/>
    </material>
   </visual>
   <collision>
    <origin rpy="0 0 0" xyz="0 0 1.5"/>
    <geometry>
     <box size="9.8 0.2 3.0"/>
    </geometry>
   </collision>
   <inertial>
    <mass value="1000"/>
    <inertia ixx="1.0" ixy="0.0" ixz="0.0" iyy="1.0" iyz="0.0" izz="1.0"/>
   </inertial>
  </link>

<joint name="world_to_wall_4" type="fixed">
    <parent link="world_frame"/>
    <child link="wall_4"/>
    <origin rpy="0 0 0" xyz="4.288 -1.037 0"/>
  </joint>

 <link name="wall_4">
   <visual>
    <geometry>
     <box size="0.2 7.63 3.0"/>
    </geometry>
    <origin rpy="0 0 0" xyz="0 0 1.5"/>
    <material name="white">
     <color rgba="1 1 1 0.5"/>
    </material>
   </visual>
   <collision>
    <origin rpy="0 0 0" xyz="0 0 1.5"/>
    <geometry>
     <box size="0.2 7.63 3.0"/>
    </geometry>
   </collision>
   <inertial>
    <mass value="1000"/>
    <inertia ixx="1.0" ixy="0.0" ixz="0.0" iyy="1.0" iyz="0.0" izz="1.0"/>
   </inertial>
  </link>

<joint name="world_to_wall_5" type="fixed">
    <parent link="world_frame"/>
    <child link="wall_5"/>
    <origin rpy="0 0 0" xyz="2.478 0.593 0"/>
  </joint>

<link name="wall_5">
   <visual>
    <geometry>
     <box size="0.28 4.37 3.0"/>
    </geometry>
    <origin rpy="0 0 0" xyz="0 0 1.5"/>
    <material name="white">
     <color rgba="1 1 1 0.5"/>
    </material>
   </visual>
   <collision>
    <origin rpy="0 0 0" xyz="0 0 1.5"/>
    <geometry>
     <box size="0.28 4.37 3.0"/>
    </geometry>
   </collision>
   <inertial>
    <mass value="1000"/>
    <inertia ixx="1.0" ixy="0.0" ixz="0.0" iyy="1.0" iyz="0.0" izz="1.0"/>
   </inertial>
  </link>

  <joint name="world_to_wall_6" type="fixed">
    <parent link="world_frame"/>
    <child link="wall_6"/>
    <origin rpy="0 0 0" xyz="2.478 -3.852 0"/>
  </joint>

  <link name="wall_6">
   <visual>
    <geometry>
     <box size="0.28 2.0 3.0"/>
    </geometry>
    <origin rpy="0 0 0" xyz="0 0 1.5"/>
    <material name="white">
     <color rgba="1 1 1 0.5"/>
    </material>
   </visual>
   <collision>
    <origin rpy="0 0 0" xyz="0 0 1.5"/>
    <geometry>
     <box size="0.28 2.0 3.0"/>
    </geometry>
   </collision>
   <inertial>
    <mass value="1000"/>
    <inertia ixx="1.0" ixy="0.0" ixz="0.0" iyy="1.0" iyz="0.0" izz="1.0"/>
   </inertial>
  </link>

<joint name="world_to_wall_7" type="fixed">
    <parent link="world_frame"/>
    <child link="wall_7"/>
    <origin rpy="0 0 0" xyz="-3.512 -3.102 0"/>
  </joint>

  <link name="wall_7">
   <visual>
    <geometry>
     <box size="0.78 0.78 3"/>
    </geometry>
    <origin rpy="0 0 0" xyz="0 0 1.5"/>
    <material name="white">
     <color rgba="1 1 1 0.5"/>
    </material>
   </visual>
   <collision>
    <origin rpy="0 0 0" xyz="0 0 1.5"/>
    <geometry>
     <box size="0.78 0.78 3"/>
    </geometry>
   </collision>
   <inertial>
    <mass value="1000"/>
    <inertia ixx="1.0" ixy="0.0" ixz="0.0" iyy="1.0" iyz="0.0" izz="1.0"/>
   </inertial>
  </link>

  <joint name="world_to_wall_8" type="fixed">
    <parent link="world_frame"/>
    <child link="wall_8"/>
    <origin rpy="0 0 0" xyz="-3.5 0.15 0"/>
  </joint>

  <link name="wall_8">
   <visual>
    <geometry>
     <box size="0.05 3.3 2"/>
    </geometry>
    <origin rpy="0 0 0" xyz="0 0 1"/>
    <material name="white">
     <color rgba="1 1 1 0.5"/>
    </material>
   </visual>
   <collision>
    <origin rpy="0 0 0" xyz="0 0 1"/>
    <geometry>
     <box size="0.05 3.3 2"/>
    </geometry>
   </collision>
   <inertial>
    <mass value="1000"/>
    <inertia ixx="1.0" ixy="0.0" ixz="0.0" iyy="1.0" iyz="0.0" izz="1.0"/>
   </inertial>
  </link>

 <joint name="world_to_wall_9" type="fixed">
    <parent link="world_frame"/>
    <child link="wall_9"/>
    <origin rpy="0 0 0" xyz="-1.1 1.8 0"/>
  </joint>

  <link name="wall_9">
   <visual>
    <geometry>
     <box size="4.8 0.05 2"/>
    </geometry>
    <origin rpy="0 0 0" xyz="0 0 1"/>
    <material name="white">
     <color rgba="1 1 1 0.5"/>
    </material>
   </visual>
   <collision>
    <origin rpy="0 0 0" xyz="0 0 1"/>
    <geometry>
     <box size="4.8 0.05 2"/>
    </geometry>
   </collision>
   <inertial>
    <mass value="1000"/>
    <inertia ixx="1.0" ixy="0.0" ixz="0.0" iyy="1.0" iyz="0.0" izz="1.0"/>
   </inertial>
  </link>


<joint name="world_to_wall_10" type="fixed">
    <parent link="world_frame"/>
    <child link="wall_10"/>
    <origin rpy="0 0 0" xyz="-1.1 -1.5 0"/>
  </joint>

  <link name="wall_10">
   <visual>
    <geometry>
     <box size="4.8 0.05 2"/>
    </geometry>
    <origin rpy="0 0 0" xyz="0 0 1"/>
    <material name="white">
     <color rgba="1 1 1 0.5"/>
    </material>
   </visual>
   <collision>
    <origin rpy="0 0 0" xyz="0 0 1"/>
    <geometry>
     <box size="4.8 0.05 2"/>
    </geometry>
   </collision>
   <inertial>
    <mass value="1000"/>
    <inertia ixx="1.0" ixy="0.0" ixz="0.0" iyy="1.0" iyz="0.0" izz="1.0"/>
   </inertial>
  </link>

<joint name="world_to_wall_11" type="fixed">
    <parent link="world_frame"/>
    <child link="wall_11"/>
    <origin rpy="0 0 0" xyz="-0.50 -3.25 0"/>
  </joint>

  <link name="wall_11">
   <visual>
    <geometry>
     <box size="0.05 3.5 2"/>
    </geometry>
    <origin rpy="0 0 0" xyz="0 0 1"/>
    <material name="white">
     <color rgba="1 1 1 0.5"/>
    </material>
   </visual>
   <collision>
    <origin rpy="0 0 0" xyz="0 0 1"/>
    <geometry>
     <box size="0.05 3.5 2"/>
    </geometry>
   </collision>
   <inertial>
    <mass value="1000"/>
    <inertia ixx="1.0" ixy="0.0" ixz="0.0" iyy="1.0" iyz="0.0" izz="1.0"/>
   </inertial>
  </link>

  <!-- table-->
 <xacro:table parent="world_frame" height="0.75" length="4.2" width="1.21"/> 


</robot>
